client log

[Log] Build ID: build-1754955453182 - Timestamp: 1754955453182 - Version: v1754955453 - Hash: hash-18uf3plrxoo (0.Cv8_sjbp.js, line 1)
[Log] Layout loaded with cache buster: – {timestamp: 1754955453182, id: "build-1754955453182", version: "v1754955453", …} (0.Cv8_sjbp.js, line 1)
{timestamp: 1754955453182, id: "build-1754955453182", version: "v1754955453", hash: "hash-18uf3plrxoo", forceRebuild: true, …}Object
[Error] Origin https://logiscore-frontend.vercel.app is not allowed by Access-Control-Allow-Origin. Status code: 500
[Error] Fetch API cannot load https://logiscorebe.onrender.com/api/freight-forwarders/?limit=18&random_select=true due to access control checks.
[Error] Failed to load resource: Origin https://logiscore-frontend.vercel.app is not allowed by Access-Control-Allow-Origin. Status code: 500 (freight-forwarders, line 0)
[Error] Failed to fetch freight forwarders:
TypeError: Load failed
	(anonymous function) (D_fXWB-Q.js:1:1268)
[Error] Failed to load homepage data:
TypeError: Load failed
	(anonymous function) (2.Bk4qIaY1.js:1:4076)

Render log

2025-08-11T23:37:33.234284558Z         self,
2025-08-11T23:37:33.234286198Z         distilled_parameters,
2025-08-11T23:37:33.234287938Z         execution_options or NO_OPTIONS,
2025-08-11T23:37:33.234289558Z     )
2025-08-11T23:37:33.234291238Z   File "/opt/render/project/src/.venv/lib/python3.13/site-packages/sqlalchemy/sql/elements.py", line 526, in _execute_on_connection
2025-08-11T23:37:33.234295588Z     return connection._execute_clauseelement(
2025-08-11T23:37:33.234297328Z            ~~~~~~~~~~~~~~~~~~~~~~~~~~~~~~~~~^
2025-08-11T23:37:33.234299048Z         self, distilled_params, execution_options
2025-08-11T23:37:33.234300688Z         ^^^^^^^^^^^^^^^^^^^^^^^^^^^^^^^^^^^^^^^^^
2025-08-11T23:37:33.234302358Z     )
2025-08-11T23:37:33.234304038Z     ^
2025-08-11T23:37:33.234305688Z   File "/opt/render/project/src/.venv/lib/python3.13/site-packages/sqlalchemy/engine/base.py", line 1641, in _execute_clauseelement
2025-08-11T23:37:33.234307418Z     ret = self._execute_context(
2025-08-11T23:37:33.234309078Z         dialect,
2025-08-11T23:37:33.234310738Z     ...<8 lines>...
2025-08-11T23:37:33.234312378Z         cache_hit=cache_hit,
2025-08-11T23:37:33.234314038Z     )
2025-08-11T23:37:33.234315728Z   File "/opt/render/project/src/.venv/lib/python3.13/site-packages/sqlalchemy/engine/base.py", line 1846, in _execute_context
2025-08-11T23:37:33.234317448Z     return self._exec_single_context(
2025-08-11T23:37:33.234319108Z            ~~~~~~~~~~~~~~~~~~~~~~~~~^
2025-08-11T23:37:33.234320799Z         dialect, context, statement, parameters
2025-08-11T23:37:33.234322679Z         ^^^^^^^^^^^^^^^^^^^^^^^^^^^^^^^^^^^^^^^
2025-08-11T23:37:33.234324308Z     )
2025-08-11T23:37:33.234325959Z     ^
2025-08-11T23:37:33.234327668Z   File "/opt/render/project/src/.venv/lib/python3.13/site-packages/sqlalchemy/engine/base.py", line 1986, in _exec_single_context
2025-08-11T23:37:33.234329339Z     self._handle_dbapi_exception(
2025-08-11T23:37:33.234331039Z     ~~~~~~~~~~~~~~~~~~~~~~~~~~~~^
2025-08-11T23:37:33.234332749Z         e, str_statement, effective_parameters, cursor, context
2025-08-11T23:37:33.234334369Z         ^^^^^^^^^^^^^^^^^^^^^^^^^^^^^^^^^^^^^^^^^^^^^^^^^^^^^^^
2025-08-11T23:37:33.234335999Z     )
2025-08-11T23:37:33.234337639Z     ^
2025-08-11T23:37:33.234339329Z   File "/opt/render/project/src/.venv/lib/python3.13/site-packages/sqlalchemy/engine/base.py", line 2355, in _handle_dbapi_exception
2025-08-11T23:37:33.234341099Z     raise sqlalchemy_exception.with_traceback(exc_info[2]) from e
2025-08-11T23:37:33.234342759Z   File "/opt/render/project/src/.venv/lib/python3.13/site-packages/sqlalchemy/engine/base.py", line 1967, in _exec_single_context
2025-08-11T23:37:33.234344449Z     self.dialect.do_execute(
2025-08-11T23:37:33.234346099Z     ~~~~~~~~~~~~~~~~~~~~~~~^
2025-08-11T23:37:33.234347769Z         cursor, str_statement, effective_parameters, context
2025-08-11T23:37:33.234356219Z         ^^^^^^^^^^^^^^^^^^^^^^^^^^^^^^^^^^^^^^^^^^^^^^^^^^^^
2025-08-11T23:37:33.234358049Z     )
2025-08-11T23:37:33.234359739Z     ^
2025-08-11T23:37:33.234361449Z   File "/opt/render/project/src/.venv/lib/python3.13/site-packages/sqlalchemy/engine/default.py", line 951, in do_execute
2025-08-11T23:37:33.234363219Z     cursor.execute(statement, parameters)
2025-08-11T23:37:33.234364939Z     ~~~~~~~~~~~~~~^^^^^^^^^^^^^^^^^^^^^^^
2025-08-11T23:37:33.234366609Z sqlalchemy.exc.ProgrammingError: (psycopg2.errors.UndefinedColumn) column reviews.overall_rating does not exist
2025-08-11T23:37:33.234368799Z LINE 1: ....updated_at AS freight_forwarders_updated_at, avg(reviews.ov...
2025-08-11T23:37:33.234370529Z                                                              ^
2025-08-11T23:37:33.234372119Z 
2025-08-11T23:37:33.234377529Z [SQL: SELECT freight_forwarders.id AS freight_forwarders_id, freight_forwarders.name AS freight_forwarders_name, freight_forwarders.website AS freight_forwarders_website, freight_forwarders.logo_url AS freight_forwarders_logo_url, freight_forwarders.description AS freight_forwarders_description, freight_forwarders.headquarters_country AS freight_forwarders_headquarters_country, freight_forwarders.global_rank AS freight_forwarders_global_rank, freight_forwarders.is_active AS freight_forwarders_is_active, freight_forwarders.created_at AS freight_forwarders_created_at, freight_forwarders.updated_at AS freight_forwarders_updated_at, avg(reviews.overall_rating) AS avg_rating, count(reviews.id) AS review_count 
2025-08-11T23:37:33.234382469Z FROM freight_forwarders LEFT OUTER JOIN reviews ON freight_forwarders.id = reviews.freight_forwarder_id GROUP BY freight_forwarders.id]
2025-08-11T23:37:33.234384289Z (Background on this error at: https://sqlalche.me/e/20/f405)